Workbook

Sheet Сводка
A1: ИТОГИ ВЕЧЕРНЕЙ УЦЕНКИ
A2: Источник: 01_выгрузка_остатков_и_продаж_1С.xlsx · Срез 19:30 · Акция 20:00–23:00
A3: Показатель | B3: Значение | D3: Метод расчёта
A4: Позиций в плане уценки | B4: =COUNTA('План 19-40'!A2:A55) -> 54 | D4: Скидка | E4: 30% от розничной цены
A5: Позиций в целевых категориях | B5: 76 | D5: Нижняя цена | E5: Себестоимость × 1,05
A6: Стоимость акционного остатка по старой цене, тг | B6: =SUMPRODUCT('План 19-40'!D2:D55,'План 19-40'!F2:F55) -> 729005 | D6: Округление | E6: Вниз до 5 тг; ниже порога — вверх до 5 тг
A7: Потенциал выручки по новой цене, тг | B7: =SUMPRODUCT('План 19-40'!E2:E55,'План 19-40'!F2:F55) -> 536765.5 | D7: Порог бракеража | E7: кг ≤ 0,5; шт./порц. ≤ 1 — бракераж
A8: Исключений и рисков | B8: =COUNTA('Исключения'!A2:A36) -> 35 | D8: Проверка срока годности | E8: Срок должен быть действителен до закрытия в 23:00
A9: Позиций для сверки штрихкода в плане | B9: =COUNTIFS('План 19-40'!H2:H55,"*BARCODE_REVIEW*") -> 7 | D9: Важное допущение | E9: Потенциал рассчитан при продаже всего остатка
A10: Цен MARGIN_ALERT утверждено | B10: =COUNTIFS('Цена скорректирована'!O2:O7,"Утверждено") -> 0 | D10: Режим MARGIN_ALERT | E10: Цена ограничивается автоматически
A11: Цен готово для кассового файла | B11: 6 | D11: Применение в кассе | E11: Передать итоговые цены на 20:00 без повторных −30%
A12: Проверка остатка в шт | B12: Только целые | D12: Источник данных | E12: 01_выгрузка_остатков_и_продаж_1С.xlsx

Sheet План 19-40
A1: Наименование | B1: Штрихкод | C1: Категория | D1: Старая цена, тг | E1: Новая цена, тг | F1: Остаток | G1: Ед. изм. | H1: Отметка
A2: Салат Греческий с сыром Фета | B2: 4870001002012 | C2: Кулинария: Салаты незаправленные | D2: 3400 | E2: =ROUNDDOWN((D2*0.7+1E-8)/5,0)*5 -> 2380 | F2: 5.5 | G2: кг | H2: Готово к наклейке
A3: Салат Витаминный из свежей капусты | B3: 4870001002029 | C3: Кулинария: Салаты незаправленные | D3: 1200 | E3: =ROUNDDOWN((D3*0.7+1E-8)/5,0)*5 -> 840 | F3: 8.2 | G3: кг | H3: Готово к наклейке
A4: Салат Свежий с огурцами и томатами | B4: 4870001002036 | C4: Кулинария: Салаты незаправленные | D4: 1800 | E4: =ROUNDDOWN((D4*0.7+1E-8)/5,0)*5 -> 1260 | F4: 6.1 | G4: кг | H4: Готово к наклейке
A5: Винегрет овощной с маслом | B5: 4870001002043 | C5: Кулинария: Салаты незаправленные | D5: 1400 | E5: =ROUNDDOWN((D5*0.7+1E-8)/5,0)*5 -> 980 | F5: 7.9 | G5: кг | H5: Готово к наклейке
A6: Салат Морковь по-корейски острая | B6: 4.60701E+12 | C6: Кулинария: Салаты незаправленные | D6: 1300 | E6: =ROUNDDOWN((D6*0.7+1E-8)/5,0)*5 -> 910 | F6: 9.4 | G6: кг | H6: BARCODE_REVIEW · сверить код в 1С до наклейки
A7: Плов Ташкентский с говядиной | B7: 4870001003019 | C7: Кулинария: Горячие блюда | D7: 2800 | E7: =ROUNDDOWN((D7*0.7+1E-8)/5,0)*5 -> 1960 | F7: 14.2 | G7: кг | H7: Готово к наклейке
A8: Манты с рубленым мясом (готовые горячие) | B8: 4870001003026 | C8: Кулинария: Горячие блюда | D8: 350 | E8: =ROUNDDOWN((D8*0.7+1E-8)/5,0)*5 -> 245 | F8: 28 | G8: шт | H8: Готово к наклейке
A9: Котлета по-киевски с маслом | B9: 4870001003033 | C9: Кулинария: Горячие блюда | D9: 650 | E9: =ROUNDDOWN((D9*0.7+1E-8)/5,0)*5 -> 455 | F9: 22 | G9: шт | H9: Готово к наклейке
A10: Тефтели мясные в томатном соусе | B10: 4870001003040 | C10: Кулинария: Горячие блюда | D10: 480 | E10: =ROUNDDOWN((D10*0.7+1E-8)/5,0)*5 -> 335 | F10: 18 | G10: шт | H10: Готово к наклейке
A11: Курица гриль целиком | B11: 4870001003057 | C11: Кулинария: Горячие блюда | D11: 2600 | E11: =ROUNDDOWN((D11*0.7+1E-8)/5,0)*5 -> 1820 | F11: 7 | G11: шт | H11: Готово к наклейке
A12: Окорочка куриные запеченные | B12: 4870001003064 | C12: Кулинария: Горячие блюда | D12: 750 | E12: =ROUNDDOWN((D12*0.7+1E-8)/5,0)*5 -> 525 | F12: 16 | G12: шт | H12: Готово к наклейке
A13: Гуляш из говядины с подливом | B13: 4870001003071 | C13: Кулинария: Горячие блюда | D13: 3600 | E13: =ROUNDDOWN((D13*0.7+1E-8)/5,0)*5 -> 2520 | F13: 6.5 | G13: кг | H13: Готово к наклейке
... A15: Казан-кебаб из баранины | B15: 4870001003095 | C15: Кулинария: Горячие блюда | D15: 4200 | E15: =ROUNDDOWN((D15*0.7+1E-8)/5,0)*5 -> 2940 | F15: 5.4 | G15: кг | H15: Готово к наклейке
A16: Стейк из семги с овощами-гриль | B16: 4870001003101 | C16: Кулинария: Горячие блюда | D16: 3500 | E16: ='Цена скорректирована'!K2 -> 2940 | F16: 6 | G16: порц | H16: Готово к наклейке; MARGIN_ALERT · итоговая цена 2 940 ₸; передать на кассу
A17: Рулет мясной 'Праздничный' из говядины | B17: 4870001003118 | C17: Кулинария: Горячие блюда | D17: 2900 | E17: ='Цена скорректирована'!K3 -> 2415 | F17: 4 | G17: порц | H17: Готово к наклейке; MARGIN_ALERT · итоговая цена 2 415 ₸; передать на кассу
A18: Картофельное пюре со сливочным маслом | B18: 4870001003125 | C18: Кулинария: Горячие блюда | D18: 1100 | E18: =ROUNDDOWN((D18*0.7+1E-8)/5,0)*5 -> 770 | F18: 9.5 | G18: кг | H18: Готово к наклейке
A19: Рис отварной рассыпчатый с овощами | B19: 4870001003132 | C19: Кулинария: Горячие блюда | D19: 1200 | E19: =ROUNDDOWN((D19*0.7+1E-8)/5,0)*5 -> 840 | F19: 7.2 | G19: кг | H19: Готово к наклейке
A20: Гречка отварная с луком и морковью | B20: 4870001003149 | C20: Кулинария: Горячие блюда | D20: 1150 | E20: =ROUNDDOWN((D20*0.7+1E-8)/5,0)*5 -> 805 | F20: 5.8 | G20: кг | H20: Готово к наклейке
A21: Макароны с сыром запеченные | C21: Кулинария: Горячие блюда | D21: 1300 | E21: =ROUNDDOWN((D21*0.7+1E-8)/5,0)*5 -> 910 | F21: 6 | G21: кг | H21: BARCODE_REVIEW · сверить код в 1С до наклейки
A22: Жаркое из курицы с грибами (партия #2) | B22: 487000105002 | C22: Кулинария: Горячие блюда | D22: 2250 | E22: =ROUNDDOWN((D22*0.7+1E-8)/5,0)*5 -> 1575 | F22: 9.1 | G22: кг | H22: Готово к наклейке
A23: Бризоль мясной с сыром (партия #3) | B23: 487000105003 | C23: Кулинария: Горячие блюда | D23: 550 | E23: =ROUNDDOWN((D23*0.7+1E-8)/5,0)*5 -> 385 | F23: 21 | G23: шт | H23: Готово к наклейке
A24: Шашлычки куриные на шпажках (партия #4) | B24: 487000105004 | C24: Кулинария: Горячие блюда | D24: 490 | E24: =ROUNDDOWN((D24*0.7+1E-8)/5,0)*5 -> 340 | F24: 28 | G24: шт | H24: Готово к наклейке
A25: Жаркое из курицы с грибами (партия #11) | B25: 487000105011;487000999011 | C25: Кулинария: Горячие блюда | D25: 2250 | E25: =ROUNDDOWN((D25*0.7+1E-8)/5,0)*5 -> 1575 | F25: 8.3 | G25: кг | H25: BARCODE_REVIEW · сверить код в 1С до наклейки
A26: Бризоль мясной с сыром (партия #12) | B26: 487000105012 | C26: Кулинария: Горячие блюда | D26: 550 | E26: =ROUNDDOWN((D26*0.7+1E-8)/5,0)*5 -> 385 | F26: 20 | G26: шт | H26: Готово к наклейке
A27: Шашлычки куриные на шпажках (партия #13) | B27: 4.60701E+12 | C27: Кулинария: Горячие блюда | D27: 490 | E27: =ROUNDDOWN((D27*0.7+1E-8)/5,0)*5 -> 340 | F27: 27 | G27: шт | H27: BARCODE_REVIEW · сверить код в 1С до наклейки
A28: Утка запеченная с яблоками (партия #14) | B28: 487000105014 | C28: Кулинария: Горячие блюда | D28: 4800 | E28: ='Цена скорректирована'!K4 -> 4410 | F28: 7 | G28: шт | H28: Готово к наклейке; MARGIN_ALERT · итоговая цена 4 410 ₸; передать на кассу
A29: Жаркое из курицы с грибами (партия #20) | B29: 487000105020 | C29: Кулинария: Горячие блюда | D29: 2250 | E29: =ROUNDDOWN((D29*0.7+1E-8)/5,0)*5 -> 1575 | F29: 7.5 | G29: кг | H29: Готово к наклейке
A30: Бризоль мясной с сыром (партия #21) | B30: 487000105021 | C30: Кулинария: Горячие блюда | D30: 550 | E30: =ROUNDDOWN((D30*0.7+1E-8)/5,0)*5 -> 385 | F30: 19 | G30: шт | H30: Готово к наклейке
A31: Шашлычки куриные на шпажках (партия #22) | B31: 487000105022;487000999022 | C31: Кулинария: Горячие блюда | D31: 490 | E31: =ROUNDDOWN((D31*0.7+1E-8)/5,0)*5 -> 340 | F31: 26 | G31: шт | H31: BARCODE_REVIEW · сверить код в 1С до наклейки
A32: Утка запеченная с яблоками (партия #23) | B32: 487000105023 | C32: Кулинария: Горячие блюда | D32: 4800 | E32: ='Цена скорректирована'!K5 -> 4410 | F32: 6 | G32: шт | H32: Готово к наклейке; MARGIN_ALERT · итоговая цена 4 410 ₸; передать на кассу
A33: Жаркое из курицы с грибами (партия #29) | B33: 487000105029 | C33: Кулинария: Горячие блюда | D33: 2250 | E33: =ROUNDDOWN((D33*0.7+1E-8)/5,0)*5 -> 1575 | F33: 10.7 | G33: кг | H33: Готово к наклейке
A34: Бризоль мясной с сыром (партия #30) | B34: 487000105030 | C34: Кулинария: Горячие блюда | D34: 550 | E34: =ROUNDDOWN((D34*0.7+1E-8)/5,0)*5 -> 385 | F34: 18 | G34: шт | H34: Готово к наклейке
A35: Шашлычки куриные на шпажках (партия #31) | B35: 487000105031 | C35: Кулинария: Горячие блюда | D35: 490 | E35: =ROUNDDOWN((D35*0.7+1E-8)/5,0)*5 -> 340 | F35: 25 | G35: шт | H35: Готово к наклейке
A36: Утка запеченная с яблоками (партия #32) | B36: 487000105032 | C36: Кулинария: Горячие блюда | D36: 4800 | E36: ='Цена скорректирована'!K6 -> 4410 | F36: 5 | G36: шт | H36: Готово к наклейке; MARGIN_ALERT · итоговая цена 4 410 ₸; передать на кассу
A37: Жаркое из курицы с грибами (партия #38) | B37: 487000105038 | C37: Кулинария: Горячие блюда | D37: 2250 | E37: =ROUNDDOWN((D37*0.7+1E-8)/5,0)*5 -> 1575 | F37: 9.9 | G37: кг | H37: Готово к наклейке
A38: Бризоль мясной с сыром (партия #39) | B38: 4.60701E+12 | C38: Кулинария: Горячие блюда | D38: 550 | E38: =ROUNDDOWN((D38*0.7+1E-8)/5,0)*5 -> 385 | F38: 27 | G38: шт | H38: BARCODE_REVIEW · сверить код в 1С до наклейки
A39: Шашлычки куриные на шпажках (партия #40) | B39: 487000105040 | C39: Кулинария: Горячие блюда | D39: 490 | E39: =ROUNDDOWN((D39*0.7+1E-8)/5,0)*5 -> 340 | F39: 24 | G39: шт | H39: Готово к наклейке
A40: Утка запеченная с яблоками (партия #41) | B40: 487000105041 | C40: Кулинария: Горячие блюда | D40: 4800 | E40: ='Цена скорректирована'!K7 -> 4410 | F40: 4 | G40: шт | H40: Готово к наклейке; MARGIN_ALERT · итоговая цена 4 410 ₸; передать на кассу
A41: Самса с мясом говядины тандырная | B41: 4870001004016 | C41: Кулинария: Выпечка и сдоба | D41: 380 | E41: =ROUNDDOWN((D41*0.7+1E-8)/5,0)*5 -> 265 | F41: 34 | G41: шт | H41: Готово к наклейке
...

Sheet Цена скорректирована
A1: Наименование | B1: Код 1С | C1: Штрихкод | D1: Категория | E1: Остаток | F1: Ед. изм. | G1: Старая цена, тг | H1: Цена −30%, тг | I1: Себестоимость, тг | J1: Порог +5%, тг | K1: Новая цена, тг | L1: Фактическая скидка | M1: Проверка штрихкода | N1: Причина корректировки | O1: Решение | P1: Утвердил | Q1: Дата и время
A2: Стейк из семги с овощами-гриль | B2: 10310 | C2: 4870001003101 | D2: Кулинария: Горячие блюда | E2: 6 | F2: порц | G2: 3500 | H2: =ROUNDDOWN((G2*0.7+1E-8)/5,0)*5 -> 2450 | I2: 2800 | J2: =I2*1.05 -> 2940 | K2: 2940 | L2: =1-K2/G2 -> 0.16 | M2: Без замечаний | N2: Скидка −30% нарушает минимальную маржу. Цена 2 940 ₸ ограничена порогом себестоимости +5%; итоговую цену нужно передать на кассу без повторных −30%. | O2: Не требуется
A3: Рулет мясной 'Праздничный' из говядины | B3: 10311 | C3: 4870001003118 | D3: Кулинария: Горячие блюда | E3: 4 | F3: порц | G3: 2900 | H3: =ROUNDDOWN((G3*0.7+1E-8)/5,0)*5 -> 2030 | I3: 2300 | J3: =I3*1.05 -> 2415 | K3: 2415 | L3: =1-K3/G3 -> 0.16724138 | M3: Без замечаний | N3: Скидка −30% нарушает минимальную маржу. Цена 2 415 ₸ ограничена порогом себестоимости +5%; итоговую цену нужно передать на кассу без повторных −30%. | O3: Не требуется
A4: Утка запеченная с яблоками (партия #14) | B4: 10514 | C4: 487000105014 | D4: Кулинария: Горячие блюда | E4: 7 | F4: шт | G4: 4800 | H4: =ROUNDDOWN((G4*0.7+1E-8)/5,0)*5 -> 3360 | I4: 4200 | J4: =I4*1.05 -> 4410 | K4: 4410 | L4: =1-K4/G4 -> 0.08125 | M4: Без замечаний | N4: Скидка −30% нарушает минимальную маржу. Цена 4 410 ₸ ограничена порогом себестоимости +5%; итоговую цену нужно передать на кассу без повторных −30%. | O4: Не требуется
A5: Утка запеченная с яблоками (партия #23) | B5: 10523 | C5: 487000105023 | D5: Кулинария: Горячие блюда | E5: 6 | F5: шт | G5: 4800 | H5: =ROUNDDOWN((G5*0.7+1E-8)/5,0)*5 -> 3360 | I5: 4200 | J5: =I5*1.05 -> 4410 | K5: 4410 | L5: =1-K5/G5 -> 0.08125 | M5: Без замечаний | N5: Скидка −30% нарушает минимальную маржу. Цена 4 410 ₸ ограничена порогом себестоимости +5%; итоговую цену нужно передать на кассу без повторных −30%. | O5: Не требуется
A6: Утка запеченная с яблоками (партия #32) | B6: 10532 | C6: 487000105032 | D6: Кулинария: Горячие блюда | E6: 5 | F6: шт | G6: 4800 | H6: =ROUNDDOWN((G6*0.7+1E-8)/5,0)*5 -> 3360 | I6: 4200 | J6: =I6*1.05 -> 4410 | K6: 4410 | L6: =1-K6/G6 -> 0.08125 | M6: Без замечаний | N6: Скидка −30% нарушает минимальную маржу. Цена 4 410 ₸ ограничена порогом себестоимости +5%; итоговую цену нужно передать на кассу без повторных −30%. | O6: Не требуется
A7: Утка запеченная с яблоками (партия #41) | B7: 10541 | C7: 487000105041 | D7: Кулинария: Горячие блюда | E7: 4 | F7: шт | G7: 4800 | H7: =ROUNDDOWN((G7*0.7+1E-8)/5,0)*5 -> 3360 | I7: 4200 | J7: =I7*1.05 -> 4410 | K7: 4410 | L7: =1-K7/G7 -> 0.08125 | M7: Без замечаний | N7: Скидка −30% нарушает минимальную маржу. Цена 4 410 ₸ ограничена порогом себестоимости +5%; итоговую цену нужно передать на кассу без повторных −30%. | O7: Не требуется

Sheet Бракераж
A1: Наименование | B1: Штрихкод | C1: Категория | D1: Остаток | E1: Ед. изм. | F1: Статус | G1: Код риска | H1: Причина | I1: Рекомендуемое действие
A2: Салат Столичный с курицей | B2: 4870001001077 | C2: Кулинария: Салаты заправленные | D2: 0.35 | E2: кг | F2: Бракераж · Срок годности | G2: LOW_STOCK, EXPIRES_BEFORE_PROMO | H2: Остаток 0,35 кг подпадает под порог бракеража (≤ 0,5 кг) — оформить акт и списание. Срок годности заканчивается ровно к 20:00 — к началу скидки продавать товар уже нельзя. | I2: Акт бракеража; Не выставлять на акцию

Sheet Исключения
A1: Наименование | B1: Штрихкод | C1: Категория | D1: Остаток | E1: Ед. изм. | F1: Статус | G1: Код риска | H1: Причина | I1: Рекомендуемое действие
A2: Салат Оливье с колбасой заправленный | B2: 4870001001015 | C2: Кулинария: Салаты заправленные | D2: 12.5 | E2: кг | F2: Срок годности | G2: EXPIRES_BEFORE_PROMO | H2: Срок годности заканчивается ровно к 20:00 — к началу скидки продавать товар уже нельзя. | I2: Не выставлять на акцию
A3: Салат Сельдь под шубой заправленный | B3: 4870001001022 | C3: Кулинария: Салаты заправленные | D3: 8.4 | E3: кг | F3: Срок годности | G3: EXPIRES_BEFORE_PROMO | H3: Срок годности заканчивается ровно к 20:00 — к началу скидки продавать товар уже нельзя. | I3: Не выставлять на акцию
A4: Салат Мимоза с горбушей | B4: 4870001001039 | C4: Кулинария: Салаты заправленные | D4: 5.2 | E4: кг | F4: Срок годности | G4: EXPIRES_BEFORE_PROMO | H4: Срок годности заканчивается ровно к 20:00 — к началу скидки продавать товар уже нельзя. | I4: Не выставлять на акцию
A5: Салат Крабовый с кукурузой заправленный | B5: 4870001001046 | C5: Кулинария: Салаты заправленные | D5: 9.1 | E5: кг | F5: Срок годности | G5: EXPIRES_BEFORE_PROMO | H5: Срок годности заканчивается ровно к 20:00 — к началу скидки продавать товар уже нельзя. | I5: Не выставлять на акцию
A6: Салат Цезарь с курицей (соус майонезный) | B6: 4870001001053 | C6: Кулинария: Салаты заправленные | D6: 6.8 | E6: кг | F6: Срок годности | G6: EXPIRES_DURING_PROMO | H6: Срок годности заканчивается во время скидки, в 20:30. Чтобы исключить продажу после срока, позиция заблокирована на весь вечер. | I6: Не клеить стикер; снять товар до истечения срока
A7: Салат Гранатовый браслет с курицей | B7: 4870001001060 | C7: Кулинария: Салаты заправленные | D7: 4.3 | E7: кг | F7: Срок годности | G7: EXPIRES_BEFORE_PROMO | H7: Срок годности заканчивается ровно к 20:00 — к началу скидки продавать товар уже нельзя. | I7: Не выставлять на акцию
A8: Салат Столичный с курицей | B8: 4870001001077 | C8: Кулинария: Салаты заправленные | D8: 0.35 | E8: кг | F8: Бракераж · Срок годности | G8: LOW_STOCK, EXPIRES_BEFORE_PROMO | H8: Остаток 0,35 кг подпадает под порог бракеража (≤ 0,5 кг) — оформить акт и списание. Срок годности заканчивается ровно к 20:00 — к началу скидки продавать товар уже нельзя. | I8: Акт бракеража; Не выставлять на акцию
A9: Салат Гнездо глухаря | B9: 4870001001084 | C9: Кулинария: Салаты заправленные | D9: 3.7 | E9: кг | F9: Срок годности | G9: EXPIRES_BEFORE_PROMO | H9: Срок годности заканчивается ровно к 20:00 — к началу скидки продавать товар уже нельзя. | I9: Не выставлять на акцию
A10: Салат Нежность с ананасом и курицей | B10: 4870001001091 | C10: Кулинария: Салаты заправленные | D10: 5 | E10: кг | F10: Срок годности | G10: EXPIRES_DURING_PROMO | H10: Срок годности заканчивается во время скидки, в 20:30. Чтобы исключить продажу после срока, позиция заблокирована на весь вечер. | I10: Не клеить стикер; снять товар до истечения срока
A11: Салат Тиффани с виноградом | B11: 4870001001107 | C11: Кулинария: Салаты заправленные | D11: 2.8 | E11: кг | F11: Срок годности | G11: EXPIRES_BEFORE_PROMO | H11: Срок годности заканчивается ровно к 20:00 — к началу скидки продавать товар уже нельзя. | I11: Не выставлять на акцию
A12: Салат Свекольный с чесноком и майонезом | B12: 4870001001114 | C12: Кулинария: Салаты заправленные | D12: 6.4 | E12: кг | F12: Срок годности | G12: EXPIRES_BEFORE_PROMO | H12: Срок годности заканчивается ровно к 20:00 — к началу скидки продавать товар уже нельзя. | I12: Не выставлять на акцию
A13: Салат Морковь по-корейски с майонезом | B13: 4870001001121;4870001001128 | C13: Кулинария: Салаты заправленные | D13: 4.1 | E13: кг | F13: Ошибка штрихкода · Срок годности | G13: BARCODE_REVIEW, EXPIRES_BEFORE_PROMO | H13: В ячейке указано несколько значений. Срок годности заканчивается ровно к 20:00 — к началу скидки продавать товар уже нельзя. | I13: Не выставлять на акцию
... A16: Рулет мясной 'Праздничный' из говядины | B16: 4870001003118 | C16: Кулинария: Горячие блюда | D16: 4 | E16: порц | F16: Маржа | G16: MARGIN_ALERT | H16: Скидка −30% нарушает минимальную маржу. Цена 2 415 ₸ ограничена порогом себестоимости +5%; итоговую цену нужно передать на кассу без повторных −30%. | I16: Передать итоговую цену на кассу к 20:00
A17: Макароны с сыром запеченные | C17: Кулинария: Горячие блюда | D17: 6 | E17: кг | F17: Проверить штрихкод | G17: MISSING_BARCODE | H17: Штрихкод не заполнен. До печати стикера и настройки скидки сверьте код в 1С. | I17: Сверить штрихкод в 1С
A18: Салат 'Фантазия' с копченой курицей (партия #1) | B18: 487000105001 | C18: Кулинария: Салаты заправленные | D18: 5.6 | E18: кг | F18: Срок годности | G18: EXPIRES_BEFORE_PROMO | H18: Срок годности заканчивается ровно к 20:00 — к началу скидки продавать товар уже нельзя. | I18: Не выставлять на акцию
A19: Утка запеченная с яблоками (партия #5) | B19: 487000105005 | C19: Кулинария: Горячие блюда | D19: 0.25 | E19: шт | F19: Ошибки данных | G19: FRACTIONAL_PIECES | H19: Остаток 0,25 шт нецелый: для единицы «шт» разрешены только целые числа. | I19: Проверить и исправить остаток в 1С
A20: Салат 'Деревенский' с картофелем (партия #9) | B20: 487000105009 | C20: Кулинария: Салаты заправленные | D20: 9.4 | E20: кг | F20: Срок годности | G20: EXPIRES_BEFORE_PROMO | H20: Срок годности заканчивается ровно к 20:00 — к началу скидки продавать товар уже нельзя. | I20: Не выставлять на акцию
A21: Салат 'Фантазия' с копченой курицей (партия #10) | B21: 487000105010 | C21: Кулинария: Салаты заправленные | D21: 4.8 | E21: кг | F21: Срок годности | G21: EXPIRES_BEFORE_PROMO | H21: Срок годности заканчивается ровно к 20:00 — к началу скидки продавать товар уже нельзя. | I21: Не выставлять на акцию
A22: Жаркое из курицы с грибами (партия #11) | B22: 487000105011;487000999011 | C22: Кулинария: Горячие блюда | D22: 8.3 | E22: кг | F22: Проверить штрихкод | G22: BARCODE_REVIEW | H22: В ячейке указано несколько значений. До печати стикера и настройки скидки сверьте код в 1С. | I22: Сверить штрихкод в 1С
A23: Шашлычки куриные на шпажках (партия #13) | B23: 4.60701E+12 | C23: Кулинария: Горячие блюда | D23: 27 | E23: шт | F23: Проверить штрихкод | G23: BARCODE_REVIEW | H23: В файле сохранена сокращённая текстовая запись. Полный исходный код нужно сверить в 1С. До печати стикера и настройки скидки сверьте код в 1С. | I23: Сверить штрихкод в 1С
A24: Утка запеченная с яблоками (партия #14) | B24: 487000105014 | C24: Кулинария: Горячие блюда | D24: 7 | E24: шт | F24: Маржа | G24: MARGIN_ALERT | H24: Скидка −30% нарушает минимальную маржу. Цена 4 410 ₸ ограничена порогом себестоимости +5%; итоговую цену нужно передать на кассу без повторных −30%. | I24: Передать итоговую цену на кассу к 20:00
A25: Салат 'Деревенский' с картофелем (партия #18) | B25: 487000105018 | C25: Кулинария: Салаты заправленные | D25: 8.6 | E25: кг | F25: Срок годности | G25: EXPIRES_BEFORE_PROMO | H25: Срок годности заканчивается ровно к 20:00 — к началу скидки продавать товар уже нельзя. | I25: Не выставлять на акцию
A26: Салат 'Фантазия' с копченой курицей (партия #19) | B26: 487000105019 | C26: Кулинария: Салаты заправленные | D26: 8 | E26: кг | F26: Срок годности | G26: EXPIRES_BEFORE_PROMO | H26: Срок годности заканчивается ровно к 20:00 — к началу скидки продавать товар уже нельзя. | I26: Не выставлять на акцию
A27: Шашлычки куриные на шпажках (партия #22) | B27: 487000105022;487000999022 | C27: Кулинария: Горячие блюда | D27: 26 | E27: шт | F27: Проверить штрихкод | G27: BARCODE_REVIEW | H27: В ячейке указано несколько значений. До печати стикера и настройки скидки сверьте код в 1С. | I27: Сверить штрихкод в 1С
A28: Утка запеченная с яблоками (партия #23) | B28: 487000105023 | C28: Кулинария: Горячие блюда | D28: 6 | E28: шт | F28: Маржа | G28: MARGIN_ALERT | H28: Скидка −30% нарушает минимальную маржу. Цена 4 410 ₸ ограничена порогом себестоимости +5%; итоговую цену нужно передать на кассу без повторных −30%. | I28: Передать итоговую цену на кассу к 20:00
A29: Салат 'Деревенский' с картофелем (партия #27) | B29: 487000105027 | C29: Кулинария: Салаты заправленные | D29: 7.8 | E29: кг | F29: Срок годности | G29: EXPIRES_BEFORE_PROMO | H29: Срок годности заканчивается ровно к 20:00 — к началу скидки продавать товар уже нельзя. | I29: Не выставлять на акцию
... A36: Утка запеченная с яблоками (партия #41) | B36: 487000105041 | C36: Кулинария: Горячие блюда | D36: 4 | E36: шт | F36: Маржа | G36: MARGIN_ALERT | H36: Скидка −30% нарушает минимальную маржу. Цена 4 410 ₸ ограничена порогом себестоимости +5%; итоговую цену нужно передать на кассу без повторных −30%. | I36: Передать итоговую цену на кассу к 20:00

Sheet Проверка целевых
A1: Наименование | B1: Штрихкод | C1: Категория | D1: Остаток | E1: Ед. изм. | F1: Статус | G1: Код риска | H1: Причина | I1: Рекомендуемое действие
A2: Салат Морковь по-корейски с майонезом | B2: 4870001001121;4870001001128 | C2: Кулинария: Салаты заправленные | D2: 4.1 | E2: кг | F2: Ошибка штрихкода · Срок годности | G2: BARCODE_REVIEW, EXPIRES_BEFORE_PROMO | H2: В ячейке указано несколько значений. Срок годности заканчивается ровно к 20:00 — к началу скидки продавать товар уже нельзя. | I2: Не выставлять на акцию
A3: Салат Морковь по-корейски острая | B3: 4.60701E+12 | C3: Кулинария: Салаты незаправленные | D3: 9.4 | E3: кг | F3: Проверить штрихкод | G3: BARCODE_REVIEW | H3: В файле сохранена сокращённая текстовая запись. Полный исходный код нужно сверить в 1С. До печати стикера и настройки скидки сверьте код в 1С. | I3: Сверить штрихкод в 1С
A4: Макароны с сыром запеченные | C4: Кулинария: Горячие блюда | D4: 6 | E4: кг | F4: Проверить штрихкод | G4: MISSING_BARCODE | H4: Штрихкод не заполнен. До печати стикера и настройки скидки сверьте код в 1С. | I4: Сверить штрихкод в 1С
A5: Утка запеченная с яблоками (партия #5) | B5: 487000105005 | C5: Кулинария: Горячие блюда | D5: 0.25 | E5: шт | F5: Ошибки данных | G5: FRACTIONAL_PIECES | H5: Остаток 0,25 шт нецелый: для единицы «шт» разрешены только целые числа. | I5: Проверить и исправить остаток в 1С
A6: Жаркое из курицы с грибами (партия #11) | B6: 487000105011;487000999011 | C6: Кулинария: Горячие блюда | D6: 8.3 | E6: кг | F6: Проверить штрихкод | G6: BARCODE_REVIEW | H6: В ячейке указано несколько значений. До печати стикера и настройки скидки сверьте код в 1С. | I6: Сверить штрихкод в 1С
A7: Шашлычки куриные на шпажках (партия #13) | B7: 4.60701E+12 | C7: Кулинария: Горячие блюда | D7: 27 | E7: шт | F7: Проверить штрихкод | G7: BARCODE_REVIEW | H7: В файле сохранена сокращённая текстовая запись. Полный исходный код нужно сверить в 1С. До печати стикера и настройки скидки сверьте код в 1С. | I7: Сверить штрихкод в 1С
A8: Шашлычки куриные на шпажках (партия #22) | B8: 487000105022;487000999022 | C8: Кулинария: Горячие блюда | D8: 26 | E8: шт | F8: Проверить штрихкод | G8: BARCODE_REVIEW | H8: В ячейке указано несколько значений. До печати стикера и настройки скидки сверьте код в 1С. | I8: Сверить штрихкод в 1С
A9: Эчпочмак с говядиной (партия #33) | B9: 487000105033;487000999033 | C9: Кулинария: Выпечка и сдоба | D9: 23 | E9: шт | F9: Проверить штрихкод | G9: BARCODE_REVIEW | H9: В ячейке указано несколько значений. До печати стикера и настройки скидки сверьте код в 1С. | I9: Сверить штрихкод в 1С
A10: Бризоль мясной с сыром (партия #39) | B10: 4.60701E+12 | C10: Кулинария: Горячие блюда | D10: 27 | E10: шт | F10: Проверить штрихкод | G10: BARCODE_REVIEW | H10: В файле сохранена сокращённая текстовая запись. Полный исходный код нужно сверить в 1С. До печати стикера и настройки скидки сверьте код в 1С. | I10: Сверить штрихкод в 1С

Sheet Срок годности
A1: Наименование | B1: Штрихкод | C1: Категория | D1: Остаток | E1: Ед. изм. | F1: Статус | G1: Код риска | H1: Причина | I1: Рекомендуемое действие
A2: Салат Оливье с колбасой заправленный | B2: 4870001001015 | C2: Кулинария: Салаты заправленные | D2: 12.5 | E2: кг | F2: Срок годности | G2: EXPIRES_BEFORE_PROMO | H2: Срок годности заканчивается ровно к 20:00 — к началу скидки продавать товар уже нельзя. | I2: Не выставлять на акцию
A3: Салат Сельдь под шубой заправленный | B3: 4870001001022 | C3: Кулинария: Салаты заправленные | D3: 8.4 | E3: кг | F3: Срок годности | G3: EXPIRES_BEFORE_PROMO | H3: Срок годности заканчивается ровно к 20:00 — к началу скидки продавать товар уже нельзя. | I3: Не выставлять на акцию
A4: Салат Мимоза с горбушей | B4: 4870001001039 | C4: Кулинария: Салаты заправленные | D4: 5.2 | E4: кг | F4: Срок годности | G4: EXPIRES_BEFORE_PROMO | H4: Срок годности заканчивается ровно к 20:00 — к началу скидки продавать товар уже нельзя. | I4: Не выставлять на акцию
A5: Салат Крабовый с кукурузой заправленный | B5: 4870001001046 | C5: Кулинария: Салаты заправленные | D5: 9.1 | E5: кг | F5: Срок годности | G5: EXPIRES_BEFORE_PROMO | H5: Срок годности заканчивается ровно к 20:00 — к началу скидки продавать товар уже нельзя. | I5: Не выставлять на акцию
A6: Салат Цезарь с курицей (соус майонезный) | B6: 4870001001053 | C6: Кулинария: Салаты заправленные | D6: 6.8 | E6: кг | F6: Срок годности | G6: EXPIRES_DURING_PROMO | H6: Срок годности заканчивается во время скидки, в 20:30. Чтобы исключить продажу после срока, позиция заблокирована на весь вечер. | I6: Не клеить стикер; снять товар до истечения срока
A7: Салат Гранатовый браслет с курицей | B7: 4870001001060 | C7: Кулинария: Салаты заправленные | D7: 4.3 | E7: кг | F7: Срок годности | G7: EXPIRES_BEFORE_PROMO | H7: Срок годности заканчивается ровно к 20:00 — к началу скидки продавать товар уже нельзя. | I7: Не выставлять на акцию
A8: Салат Столичный с курицей | B8: 4870001001077 | C8: Кулинария: Салаты заправленные | D8: 0.35 | E8: кг | F8: Бракераж · Срок годности | G8: LOW_STOCK, EXPIRES_BEFORE_PROMO | H8: Остаток 0,35 кг подпадает под порог бракеража (≤ 0,5 кг) — оформить акт и списание. Срок годности заканчивается ровно к 20:00 — к началу скидки продавать товар уже нельзя. | I8: Акт бракеража; Не выставлять на акцию
A9: Салат Гнездо глухаря | B9: 4870001001084 | C9: Кулинария: Салаты заправленные | D9: 3.7 | E9: кг | F9: Срок годности | G9: EXPIRES_BEFORE_PROMO | H9: Срок годности заканчивается ровно к 20:00 — к началу скидки продавать товар уже нельзя. | I9: Не выставлять на акцию
A10: Салат Нежность с ананасом и курицей | B10: 4870001001091 | C10: Кулинария: Салаты заправленные | D10: 5 | E10: кг | F10: Срок годности | G10: EXPIRES_DURING_PROMO | H10: Срок годности заканчивается во время скидки, в 20:30. Чтобы исключить продажу после срока, позиция заблокирована на весь вечер. | I10: Не клеить стикер; снять товар до истечения срока
A11: Салат Тиффани с виноградом | B11: 4870001001107 | C11: Кулинария: Салаты заправленные | D11: 2.8 | E11: кг | F11: Срок годности | G11: EXPIRES_BEFORE_PROMO | H11: Срок годности заканчивается ровно к 20:00 — к началу скидки продавать товар уже нельзя. | I11: Не выставлять на акцию
A12: Салат Свекольный с чесноком и майонезом | B12: 4870001001114 | C12: Кулинария: Салаты заправленные | D12: 6.4 | E12: кг | F12: Срок годности | G12: EXPIRES_BEFORE_PROMO | H12: Срок годности заканчивается ровно к 20:00 — к началу скидки продавать товар уже нельзя. | I12: Не выставлять на акцию
A13: Салат Морковь по-корейски с майонезом | B13: 4870001001121;4870001001128 | C13: Кулинария: Салаты заправленные | D13: 4.1 | E13: кг | F13: Ошибка штрихкода · Срок годности | G13: BARCODE_REVIEW, EXPIRES_BEFORE_PROMO | H13: В ячейке указано несколько значений. Срок годности заканчивается ровно к 20:00 — к началу скидки продавать товар уже нельзя. | I13: Не выставлять на акцию
... A22: Салат 'Фантазия' с копченой курицей (партия #37) | B22: 487000105037 | C22: Кулинария: Салаты заправленные | D22: 6.4 | E22: кг | F22: Срок годности | G22: EXPIRES_BEFORE_PROMO | H22: Срок годности заканчивается ровно к 20:00 — к началу скидки продавать товар уже нельзя. | I22: Не выставлять на акцию
